2025-05-09 23:33:21,258 - root - INFO - Loaded cog: course_availability.py
2025-05-09 23:33:21,262 - root - INFO - Loaded cog: heat_outline.py
2025-05-09 23:33:21,264 - root - INFO - Loaded cog: course_info.py
2025-05-09 23:33:21,264 - discord.client - INFO - logging in using static token
2025-05-09 23:33:22,609 - discord.gateway - INFO - Shard ID None has connected to Gateway (Session ID: 08984610d5d6a08c42e49d4fde045f52).
2025-05-09 23:33:24,614 - root - INFO - Bot is logged in as UVIC Course Info Test (1370471918859190403)
2025-05-09 23:33:48,390 - cogs.heat_outline - INFO - Received heat outline command: ECE 455 011 2025
2025-05-09 23:33:48,721 - discord.app_commands.tree - ERROR - Ignoring exception in command 'heat'
Traceback (most recent call last):
  File "/usr/local/lib/python3.12/site-packages/discord/app_commands/commands.py", line 857, in _do_call
    return await self._callback(self.binding, interaction, **params)  # type: ignore
           ^^^^^^^^^^^^^^^^^^^^^^^^^^^^^^^^^^^^^^^^^^^^^^^^^^^^^^^^^
  File "/app/cogs/heat_outline.py", line 50, in heat
    await interaction.response.send_message(heat_url.error)
  File "/usr/local/lib/python3.12/site-packages/discord/interactions.py", line 976, in send_message
    raise InteractionResponded(self._parent)
discord.errors.InteractionResponded: This interaction has already been responded to before

The above exception was the direct cause of the following exception:

Traceback (most recent call last):
  File "/usr/local/lib/python3.12/site-packages/discord/app_commands/tree.py", line 1310, in _call
    await command._invoke_with_namespace(interaction, namespace)
  File "/usr/local/lib/python3.12/site-packages/discord/app_commands/commands.py", line 883, in _invoke_with_namespace
    return await self._do_call(interaction, transformed_values)
           ^^^^^^^^^^^^^^^^^^^^^^^^^^^^^^^^^^^^^^^^^^^^^^^^^^^^
  File "/usr/local/lib/python3.12/site-packages/discord/app_commands/commands.py", line 876, in _do_call
    raise CommandInvokeError(self, e) from e
discord.app_commands.errors.CommandInvokeError: Command 'heat' raised an exception: InteractionResponded: This interaction has already been responded to before
2025-05-09 23:34:44,695 - root - INFO - Loaded cog: course_availability.py
2025-05-09 23:34:44,699 - root - INFO - Loaded cog: heat_outline.py
2025-05-09 23:34:44,700 - root - INFO - Loaded cog: course_info.py
2025-05-09 23:34:44,701 - discord.client - INFO - logging in using static token
2025-05-09 23:34:45,828 - discord.gateway - INFO - Shard ID None has connected to Gateway (Session ID: 6a7302af98359936b3922bc434a1ad8c).
2025-05-09 23:34:47,833 - root - INFO - Bot is logged in as UVIC Course Info Test (1370471918859190403)
2025-05-09 23:34:52,945 - cogs.heat_outline - INFO - Received heat outline command: ECE 455 011 2025
2025-05-09 23:34:53,235 - discord.app_commands.tree - ERROR - Ignoring exception in command 'heat'
Traceback (most recent call last):
  File "/usr/local/lib/python3.12/site-packages/discord/app_commands/commands.py", line 857, in _do_call
    return await self._callback(self.binding, interaction, **params)  # type: ignore
           ^^^^^^^^^^^^^^^^^^^^^^^^^^^^^^^^^^^^^^^^^^^^^^^^^^^^^^^^^
  File "/app/cogs/heat_outline.py", line 49, in heat
    if not heat_url.is_valid:
           ^^^^^^^^^^^^^^^^^
AttributeError: 'HeatUrl' object has no attribute 'is_valid'

The above exception was the direct cause of the following exception:

Traceback (most recent call last):
  File "/usr/local/lib/python3.12/site-packages/discord/app_commands/tree.py", line 1310, in _call
    await command._invoke_with_namespace(interaction, namespace)
  File "/usr/local/lib/python3.12/site-packages/discord/app_commands/commands.py", line 883, in _invoke_with_namespace
    return await self._do_call(interaction, transformed_values)
           ^^^^^^^^^^^^^^^^^^^^^^^^^^^^^^^^^^^^^^^^^^^^^^^^^^^^
  File "/usr/local/lib/python3.12/site-packages/discord/app_commands/commands.py", line 876, in _do_call
    raise CommandInvokeError(self, e) from e
discord.app_commands.errors.CommandInvokeError: Command 'heat' raised an exception: AttributeError: 'HeatUrl' object has no attribute 'is_valid'
2025-05-09 23:35:28,362 - root - INFO - Loaded cog: course_availability.py
2025-05-09 23:35:28,365 - root - INFO - Loaded cog: heat_outline.py
2025-05-09 23:35:28,367 - root - INFO - Loaded cog: course_info.py
2025-05-09 23:35:28,367 - discord.client - INFO - logging in using static token
2025-05-09 23:35:29,340 - discord.gateway - INFO - Shard ID None has connected to Gateway (Session ID: 930d5c1d696b7f28fb9e72b723be3162).
2025-05-09 23:35:31,345 - root - INFO - Bot is logged in as UVIC Course Info Test (1370471918859190403)
2025-05-09 23:35:32,024 - cogs.heat_outline - INFO - Received heat outline command: ECE 455 011 2025
2025-05-09 23:35:32,284 - discord.app_commands.tree - ERROR - Ignoring exception in command 'heat'
Traceback (most recent call last):
  File "/usr/local/lib/python3.12/site-packages/discord/app_commands/commands.py", line 857, in _do_call
    return await self._callback(self.binding, interaction, **params)  # type: ignore
           ^^^^^^^^^^^^^^^^^^^^^^^^^^^^^^^^^^^^^^^^^^^^^^^^^^^^^^^^^
  File "/app/cogs/heat_outline.py", line 49, in heat
    if not heat_url.is_valid:
           ^^^^^^^^^^^^^^^^^
AttributeError: 'HeatUrl' object has no attribute 'is_valid'

The above exception was the direct cause of the following exception:

Traceback (most recent call last):
  File "/usr/local/lib/python3.12/site-packages/discord/app_commands/tree.py", line 1310, in _call
    await command._invoke_with_namespace(interaction, namespace)
  File "/usr/local/lib/python3.12/site-packages/discord/app_commands/commands.py", line 883, in _invoke_with_namespace
    return await self._do_call(interaction, transformed_values)
           ^^^^^^^^^^^^^^^^^^^^^^^^^^^^^^^^^^^^^^^^^^^^^^^^^^^^
  File "/usr/local/lib/python3.12/site-packages/discord/app_commands/commands.py", line 876, in _do_call
    raise CommandInvokeError(self, e) from e
discord.app_commands.errors.CommandInvokeError: Command 'heat' raised an exception: AttributeError: 'HeatUrl' object has no attribute 'is_valid'
2025-05-09 23:36:36,287 - root - INFO - Loaded cog: course_availability.py
2025-05-09 23:36:36,291 - root - INFO - Loaded cog: heat_outline.py
2025-05-09 23:36:36,293 - root - INFO - Loaded cog: course_info.py
2025-05-09 23:36:36,293 - discord.client - INFO - logging in using static token
2025-05-09 23:36:37,371 - discord.gateway - INFO - Shard ID None has connected to Gateway (Session ID: e1e1970a961415fdb5d5232c7024acc3).
2025-05-09 23:36:39,377 - root - INFO - Bot is logged in as UVIC Course Info Test (1370471918859190403)
2025-05-09 23:36:39,661 - cogs.heat_outline - INFO - Received heat outline command: ECE 455 011 2025
2025-05-09 23:43:00,083 - root - INFO - Loaded cog: course_availability.py
2025-05-09 23:43:00,087 - root - INFO - Loaded cog: heat_outline.py
2025-05-09 23:43:00,088 - root - INFO - Loaded cog: course_info.py
2025-05-09 23:43:00,089 - discord.client - INFO - logging in using static token
2025-05-09 23:43:01,493 - discord.gateway - INFO - Shard ID None has connected to Gateway (Session ID: 575663847831c00dfa1242675efeb48d).
2025-05-09 23:43:03,499 - root - INFO - Bot is logged in as UVIC Course Info Test (1370471918859190403)
2025-05-09 23:43:04,310 - cogs.heat_outline - INFO - Received heat outline command: ECE 455 011 2025
2025-05-09 23:45:15,594 - root - INFO - Loaded cog: course_availability.py
2025-05-09 23:45:15,598 - root - INFO - Loaded cog: heat_outline.py
2025-05-09 23:45:15,599 - root - INFO - Loaded cog: course_info.py
2025-05-09 23:45:15,599 - discord.client - INFO - logging in using static token
2025-05-09 23:45:17,079 - discord.gateway - INFO - Shard ID None has connected to Gateway (Session ID: 7c5120518237f2d335eed66a97bcb297).
2025-05-09 23:45:19,085 - root - INFO - Bot is logged in as UVIC Course Info Test (1370471918859190403)
2025-05-09 23:45:22,105 - cogs.heat_outline - INFO - Received heat outline command: ECE 455 011 2025
